Workbook
Name Slicer_Diabetes_Status: #N/A
Name Slicer_Weight_Status: #N/A

Sheet CUSTOMER NAMES
A1: Customer ID | B1: name
A2: Id1 | B2: Hawks, Ms. Kelly
A3: Id2 | B3: Lehner, Mr. Matthew D
A4: Id3 | B4: Lu, Mr. Phil
A5: Id4 | B5: Osborne, Ms. Kelsey
A6: Id5 | B6: Kadala, Ms. Kristyn
A7: Id6 | B7: Baker, Mr. Russell B.
A8: Id7 | B8: Macpherson, Mr. Scott
A9: Id8 | B9: Hallman, Mr. Stephen
A10: Id9 | B10: Moran, Mr. Patrick R.
A11: Id10 | B11: Benner, Ms. Brooke N.
A12: Id11 | B12: Fierro Vargas, Ms. Paola Andrea
... A2336: Id2335 | B2336: German, Mr. Aaron K

Sheet MEDICAL EXAMINATIONS
A1: Customer ID | B1: BMI | C1: HBA1C | D1: Heart Issues | E1: Any Transplants | F1: Cancer history | G1: NumberOfMajorSurgeries | H1: smoker
A2: Id1 | B2: 47.41 | C2: 7.47 | D2: No | E2: No | F2: No | G2: No major surgery | H2: yes
A3: Id2 | B3: 30.36 | C3: 5.77 | D3: No | E3: No | F3: No | G3: No major surgery | H3: yes
A4: Id3 | B4: 34.485 | C4: 11.87 | D4: yes | E4: No | F4: No | G4: 2 | H4: yes
A5: Id4 | B5: 38.095 | C5: 6.05 | D5: No | E5: No | F5: No | G5: No major surgery | H5: yes
A6: Id5 | B6: 35.53 | C6: 5.45 | D6: No | E6: No | F6: No | G6: No major surgery | H6: yes
A7: Id6 | B7: 32.8 | C7: 6.59 | D7: No | E7: No | F7: No | G7: No major surgery | H7: yes
A8: Id7 | B8: 36.4 | C8: 6.07 | D8: No | E8: No | F8: No | G8: No major surgery | H8: yes
A9: Id8 | B9: 36.96 | C9: 7.93 | D9: No | E9: No | F9: No | G9: 3 | H9: yes
A10: Id9 | B10: 41.14 | C10: 9.58 | D10: yes | E10: No | F10: Yes | G10: 1 | H10: yes
A11: Id10 | B11: 38.06 | C11: 10.79 | D11: No | E11: No | F11: No | G11: No major surgery | H11: yes
A12: Id11 | B12: 37.7 | C12: 5.96 | D12: yes | E12: No | F12: No | G12: 2 | H12: yes
A13: Id12 | B13: 42.13 | C13: 11.9 | D13: No | E13: No | F13: No | G13: No major surgery | H13: yes
A14: Id13 | B14: 40.92 | C14: 8.41 | D14: No | E14: No | F14: No | G14: No major surgery | H14: yes
A15: Id14 | B15: 40.565 | C15: 7.02 | D15: No | E15: No | F15: No | G15: No major surgery | H15: yes
A16: Id15 | B16: 36.385 | C16: 7.59 | D16: yes | E16: No | F16: No | G16: 2 | H16: yes
A17: Id16 | B17: 39.9 | C17: 11.32 | D17: No | E17: No | F17: No | G17: No major surgery | H17: yes
A18: Id17 | B18: 33.8 | C18: 7.67 | D18: No | E18: No | F18: No | G18: 3 | H18: yes
A19: Id18 | B19: 36.765 | C19: 7.29 | D19: yes | E19: No | F19: Yes | G19: 1 | H19: yes
A20: Id19 | B20: 36.955 | C20: 4.72 | D20: yes | E20: No | F20: No | G20: 1 | H20: yes
A21: Id20 | B21: 42.9 | C21: 11.41 | D21: No | E21: No | F21: No | G21: No major surgery | H21: yes
A22: Id21 | B22: 36.3 | C22: 11.5 | D22: yes | E22: No | F22: No | G22: 2 | H22: yes
A23: Id22 | B23: 32.2 | C23: 6.22 | D23: yes | E23: No | F23: No | G23: 2 | H23: yes
A24: Id23 | B24: 31.3 | C24: 11.38 | D24: No | E24: No | F24: No | G24: 3 | H24: yes
A25: Id24 | B25: 41.8 | C25: 7.89 | D25: yes | E25: No | F25: No | G25: 2 | H25: yes
A26: Id25 | B26: 35.09 | C26: 4.38 | D26: yes | E26: No | F26: No | G26: 2 | H26: yes
A27: Id26 | B27: 33.88 | C27: 7.01 | D27: No | E27: No | F27: No | G27: 3 | H27: yes
A28: Id27 | B28: 30.875 | C28: 11.88 | D28: No | E28: No | F28: No | G28: No major surgery | H28: yes
A29: Id28 | B29: 36.86 | C29: 5.19 | D29: yes | E29: No | F29: Yes | G29: 1 | H29: yes
A30: Id29 | B30: 35.86 | C30: 6.74 | D30: yes | E30: No | F30: No | G30: 2 | H30: yes
A31: Id30 | B31: 37.05 | C31: 8.44 | D31: No | E31: No | F31: No | G31: No major surgery | H31: yes
A32: Id31 | B32: 43.89 | C32: 8.71 | D32: No | E32: No | F32: No | G32: No major surgery | H32: yes
A33: Id32 | B33: 42.35 | C33: 5.08 | D33: yes | E33: No | F33: No | G33: No major surgery | H33: yes
A34: Id33 | B34: 31.35 | C34: 6.86 | D34: No | E34: No | F34: No | G34: No major surgery | H34: yes
A35: Id34 | B35: 47.6 | C35: 5.95 | D35: yes | E35: No | F35: No | G35: No major surgery | H35: yes
A36: Id35 | B36: 46.2 | C36: 6.09 | D36: No | E36: No | F36: Yes | G36: 1 | H36: yes
A37: Id36 | B37: 32.015 | C37: 11.75 | D37: No | E37: No | F37: No | G37: No major surgery | H37: yes
A38: Id37 | B38: 40.565 | C38: 7.37 | D38: No | E38: No | F38: No | G38: No major surgery | H38: yes
A39: Id38 | B39: 32.45 | C39: 11.91 | D39: No | E39: No | F39: No | G39: No major surgery | H39: yes
A40: Id39 | B40: 34.96 | C40: 6.52 | D40: No | E40: No | F40: No | G40: No major surgery | H40: yes
...

Sheet HOSPITALISATION DETAILS
A1: Customer ID | B1: year | C1: month | D1: date | E1: children | F1: charges | G1: Hospital tier | H1: City tier | I1: State ID
A2: Id2335 | B2: 1992 | C2: Jul | D2: 9 | E2: 0 | F2: 563.84 | G2: tier - 2 | H2: tier - 3 | I2: R1013
A3: Id2334 | B3: 1992 | C3: Nov | D3: 30 | E3: 0 | F3: 570.62 | G3: tier - 2 | H3: tier - 1 | I3: R1013
A4: Id2333 | B4: 1993 | C4: Jun | D4: 30 | E4: 0 | F4: 600 | G4: tier - 2 | H4: tier - 1 | I4: R1013
A5: Id2332 | B5: 1992 | C5: Sep | D5: 13 | E5: 0 | F5: 604.54 | G5: tier - 3 | H5: tier - 3 | I5: R1013
A6: Id2331 | B6: 1998 | C6: Jul | D6: 27 | E6: 0 | F6: 637.26 | G6: tier - 3 | H6: tier - 3 | I6: R1013
A7: Id2330 | B7: 2001 | C7: Nov | D7: 20 | E7: 0 | F7: 646.14 | G7: tier - 3 | H7: tier - 3 | I7: R1012
A8: Id2329 | B8: 1993 | C8: Jun | D8: 1 | E8: 0 | F8: 650 | G8: tier - 3 | H8: tier - 3 | I8: R1013
A9: Id2328 | B9: 1995 | C9: Jul | D9: 4 | E9: 0 | F9: 650 | G9: tier - 3 | H9: tier - 3 | I9: R1013
A10: Id2327 | B10: 2002 | C10: Nov | D10: 29 | E10: 0 | F10: 668 | G10: tier - 3 | H10: tier - 2 | I10: R1012
A11: Id2326 | B11: 1997 | C11: Nov | D11: 9 | E11: 0 | F11: 670 | G11: tier - 3 | H11: tier - 3 | I11: R1013
A12: Id2325 | B12: 2001 | C12: Sep | D12: 12 | E12: 0 | F12: 687.54 | G12: tier - 3 | H12: tier - 2 | I12: R1013
A13: Id2324 | B13: 1999 | C13: Dec | D13: 26 | E13: 0 | F13: 700 | G13: ? | H13: tier - 3 | I13: R1013
... A1050: Id1290 | B1050: 1977 | C1050: Jul | D1050: 26 | E1050: 2 | F1050: 8527.53 | G1050: tier - 2 | H1050: tier - 2 | I1050: R1013
A1051: Id1289 | B1051: ? | C1051: Jul | D1051: 24 | E1051: 0 | F1051: 8534.67 | G1051: tier - 2 | H1051: tier - 3 | I1051: R1024
A1052: Id1288 | B1052: 1981 | C1052: Dec | D1052: 27 | E1052: 3 | F1052: 8538.29 | G1052: tier - 2 | H1052: tier - 3 | I1052: R1024
A1053: Id1287 | B1053: 1975 | C1053: Nov | D1053: 6 | E1053: 1 | F1053: 8539.67 | G1053: tier - 2 | H1053: tier - 3 | I1053: R1011
A1054: Id1286 | B1054: ? | C1054: Dec | D1054: 12 | E1054: 1 | F1054: 8547.69 | G1054: tier - 2 | H1054: tier - 1 | I1054: R1013
A1055: Id1285 | B1055: 1975 | C1055: Aug | D1055: 6 | E1055: 1 | F1055: 8551.35 | G1055: tier - 2 | H1055: tier - 2 | I1055: R1011
A1056: Id1284 | B1056: 1975 | C1056: Aug | D1056: 21 | E1056: 1 | F1056: 8556.91 | G1056: tier - 2 | H1056: tier - 1 | I1056: R1011
A1057: Id1283 | B1057: 1988 | C1057: Sep | D1057: 21 | E1057: 3 | F1057: 8567.25 | G1057: tier - 2 | H1057: tier - 1 | I1057: R1012
A1058: Id1282 | B1058: 1975 | C1058: Sep | D1058: 26 | E1058: 1 | F1058: 8569.86 | G1058: tier - 2 | H1058: tier - 3 | I1058: R1013
A1059: Id1281 | B1059: 1982 | C1059: Dec | D1059: 6 | E1059: 3 | F1059: 8572.04 | G1059: tier - 2 | H1059: tier - 2 | I1059: R1021
A1060: Id1280 | B1060: 1987 | C1060: Nov | D1060: 11 | E1060: 3 | F1060: 8573.3 | G1060: tier - 2 | H1060: tier - 2 | I1060: R1021
A1061: Id1279 | B1061: 1983 | C1061: Dec | D1061: 30 | E1061: 5 | F1061: 8582.3 | G1061: tier - 2 | H1061: tier - 1 | I1061: R1013
A1062: Id1278 | B1062: 1983 | C1062: Jul | D1062: 25 | E1062: 5 | F1062: 8596.83 | G1062: tier - 2 | H1062: tier - 3 | I1062: R1013
A1063: Id1277 | B1063: 1973 | C1063: Jul | D1063: 11 | E1063: 0 | F1063: 8601.33 | G1063: tier - 2 | H1063: tier - 1 | I1063: R1013
A1064: Id1276 | B1064: 1977 | C1064: Sep | D1064: 24 | E1064: 2 | F1064: 8603.82 | G1064: tier - 2 | H1064: tier - 1 | I1064: R1019
A1065: Id1275 | B1065: 1977 | C1065: Nov | D1065: 12 | E1065: 2 | F1065: 8604.48 | G1065: tier - 3 | H1065: tier - 2 | I1065: R1016
A1066: Id1274 | B1066: 1977 | C1066: Oct | D1066: 15 | E1066: 3 | F1066: 8605.36 | G1066: tier - 2 | H1066: tier - 2 | I1066: R1013
... A2344: Id1 | B2344: 1968 | C2344: Oct | D2344: 12 | E2344: 0 | F2344: 63770.43 | G2344: tier - 1 | H2344: tier - 3 | I2344: R1013

Sheet DATA CLEANING 1
A1: The number of missing values in "Medical Examinations" table. | H1: Customer ID | I1: BMI | J1: HBA1C | K1: Heart Issues | L1: Any Transplants | M1: Cancer history | N1: NumberOfMajorSurgeries | O1: smoker | Q1: Customer ID | R1: year | S1: month | T1: date | U1: children | V1: charges | W1: Hospital tier | X1: City tier | Y1: State ID
F2: =COUNTIF(H:O, "?") -> 2 | H2: Id1 | I2: 47.41 | J2: 7.47 | K2: No | L2: No | M2: No | N2: No major surgery | O2: yes | Q2: Id2335 | R2: 1992 | S2: Jul | T2: 9 | U2: 0 | V2: 563.84 | W2: tier - 2 | X2: tier - 3 | Y2: R1013
H3: Id2 | I3: 30.36 | J3: 5.77 | K3: No | L3: No | M3: No | N3: No major surgery | O3: yes | Q3: Id2334 | R3: 1992 | S3: Nov | T3: 30 | U3: 0 | V3: 570.62 | W3: tier - 2 | X3: tier - 1 | Y3: R1013
A4: The number of missing values in the "Hospitalisation Details" table. | F4: =COUNTIF(Q:Y, "?") -> 15 | H4: Id3 | I4: 34.485 | J4: 11.87 | K4: yes | L4: No | M4: No | N4: 2 | O4: yes | Q4: Id2333 | R4: 1993 | S4: Jun | T4: 30 | U4: 0 | V4: 600 | W4: tier - 2 | X4: tier - 1 | Y4: R1013
H5: Id4 | I5: 38.095 | J5: 6.05 | K5: No | L5: No | M5: No | N5: No major surgery | O5: yes | Q5: Id2332 | R5: 1992 | S5: Sep | T5: 13 | U5: 0 | V5: 604.54 | W5: tier - 3 | X5: tier - 3 | Y5: R1013
H6: Id5 | I6: 35.53 | J6: 5.45 | K6: No | L6: No | M6: No | N6: No major surgery | O6: yes | Q6: Id2331 | R6: 1998 | S6: Jul | T6: 27 | U6: 0 | V6: 637.26 | W6: tier - 3 | X6: tier - 3 | Y6: R1013
H7: Id6 | I7: 32.8 | J7: 6.59 | K7: No | L7: No | M7: No | N7: No major surgery | O7: yes | Q7: Id2330 | R7: 2001 | S7: Nov | T7: 20 | U7: 0 | V7: 646.14 | W7: tier - 3 | X7: tier - 3 | Y7: R1012
H8: Id7 | I8: 36.4 | J8: 6.07 | K8: No | L8: No | M8: No | N8: No major surgery | O8: yes | Q8: Id2329 | R8: 1993 | S8: Jun | T8: 1 | U8: 0 | V8: 650 | W8: tier - 3 | X8: tier - 3 | Y8: R1013
H9: Id8 | I9: 36.96 | J9: 7.93 | K9: No | L9: No | M9: No | N9: 3 | O9: yes | Q9: Id2328 | R9: 1995 | S9: Jul | T9: 4 | U9: 0 | V9: 650 | W9: tier - 3 | X9: tier - 3 | Y9: R1013
H10: Id9 | I10: 41.14 | J10: 9.58 | K10: yes | L10: No | M10: Yes | N10: 1 | O10: yes | Q10: Id2327 | R10: 2002 | S10: Nov | T10: 29 | U10: 0 | V10: 668 | W10: tier - 3 | X10: tier - 2 | Y10: R1012
H11: Id10 | I11: 38.06 | J11: 10.79 | K11: No | L11: No | M11: No | N11: No major surgery | O11: yes | Q11: Id2326 | R11: 1997 | S11: Nov | T11: 9 | U11: 0 | V11: 670 | W11: tier - 3 | X11: tier - 3 | Y11: R1013
H12: Id11 | I12: 37.7 | J12: 5.96 | K12: yes | L12: No | M12: No | N12: 2 | O12: yes | Q12: Id2325 | R12: 2001 | S12: Sep | T12: 12 | U12: 0 | V12: 687.54 | W12: tier - 3 | X12: tier - 2 | Y12: R1013
H13: Id12 | I13: 42.13 | J13: 11.9 | K13: No | L13: No | M13: No | N13: No major surgery | O13: yes | Q13: Id2324 | R13: 1999 | S13: Dec | T13: 26 | U13: 0 | V13: 700 | W13: ? | X13: tier - 3 | Y13: R1013
H14: Id13 | I14: 40.92 | J14: 8.41 | K14: No | L14: No | M14: No | N14: No major surgery | O14: yes | Q14: Id2323 | R14: 1999 | S14: Dec | T14: 14 | U14: 0 | V14: 722.99 | W14: tier - 3 | X14: tier - 1 | Y14: R1013
H15: Id14 | I15: 40.565 | J15: 7.02 | K15: No | L15: No | M15: No | N15: No major surgery | O15: yes | Q15: Id2322 | R15: 2002 | S15: ? | T15: 19 | U15: 0 | V15: 750 | W15: tier - 3 | X15: tier - 1 | Y15: R1012
H16: Id15 | I16: 36.385 | J16: 7.59 | K16: yes | L16: No | M16: No | N16: 2 | O16: yes | Q16: Id2321 | R16: 1993 | S16: Aug | T16: 9 | U16: 0 | V16: 760 | W16: tier - 3 | X16: tier - 1 | Y16: R1013
H17: Id16 | I17: 39.9 | J17: 11.32 | K17: No | L17: No | M17: No | N17: No major surgery | O17: yes | Q17: Id2320 | R17: 1996 | S17: Oct | T17: 22 | U17: 0 | V17: 760 | W17: tier - 3 | X17: tier - 3 | Y17: R1013
H18: Id17 | I18: 33.8 | J18: 7.67 | K18: No | L18: No | M18: No | N18: 3 | O18: yes | Q18: Id2319 | R18: 1993 | S18: Jun | T18: 28 | U18: 0 | V18: 770 | W18: tier - 3 | X18: tier - 3 | Y18: R1013
H19: Id18 | I19: 36.765 | J19: 7.29 | K19: yes | L19: No | M19: Yes | N19: 1 | O19: yes | Q19: Id2318 | R19: 1996 | S19: ? | T19: 18 | U19: 0 | V19: 770.38 | W19: tier - 3 | X19: ? | Y19: R1012
H20: Id19 | I20: 36.955 | J20: 4.72 | K20: yes | L20: No | M20: No | N20: 1 | O20: yes | Q20: Id2317 | R20: 1995 | S20: Dec | T20: 7 | U20: 0 | V20: 773.54 | W20: tier - 3 | X20: tier - 2 | Y20: R1013
H21: Id20 | I21: 42.9 | J21: 11.41 | K21: No | L21: No | M21: No | N21: No major surgery | O21: yes | Q21: Id2316 | R21: 2004 | S21: Oct | T21: 7 | U21: 0 | V21: 830.52 | W21: tier - 3 | X21: tier - 2 | Y21: R1011
H22: Id21 | I22: 36.3 | J22: 11.5 | K22: yes | L22: No | M22: No | N22: 2 | O22: yes | Q22: Id2315 | R22: 2000 | S22: Nov | T22: 18 | U22: 0 | V22: 865.41 | W22: tier - 3 | X22: tier - 1 | Y22: R1013
H23: Id22 | I23: 32.2 | J23: 6.22 | K23: yes | L23: No | M23: No | N23: 2 | O23: yes | Q23: Id2314 | R23: 1993 | S23: Nov | T23: 27 | U23: 0 | V23: 896.21 | W23: tier - 3 | X23: tier - 1 | Y23: R1013
H24: Id23 | I24: 31.3 | J24: 11.38 | K24: No | L24: No | M24: No | N24: 3 | O24: yes | Q24: Id2313 | R24: 1994 | S24: Oct | T24: 30 | U24: 0 | V24: 915.07 | W24: tier - 3 | X24: tier - 1 | Y24: R1013
H25: Id24 | I25: 41.8 | J25: 7.89 | K25: yes | L25: No | M25: No | N25: 2 | O25: yes | Q25: Id2312 | R25: 1995 | S25: Oct | T25: 28 | U25: 0 | V25: 928.59 | W25: tier - 3 | X25: tier - 1 | Y25: R1013
H26: Id25 | I26: 35.09 | J26: 4.38 | K26: yes | L26: No | M26: No | N26: 2 | O26: yes | Q26: Id2311 | R26: 2001 | S26: Aug | T26: 19 | U26: 0 | V26: 964.71 | W26: tier - 3 | X26: tier - 2 | Y26: R1013
H27: Id26 | I27: 33.88 | J27: 7.01 | K27: No | L27: No | M27: No | N27: 3 | O27: yes | Q27: Id2310 | R27: 1994 | S27: Nov | T27: 22 | U27: 0 | V27: 1006.65 | W27: tier - 3 | X27: tier - 2 | Y27: R1013
H28: Id27 | I28: 30.875 | J28: 11.88 | K28: No | L28: No | M28: No | N28: No major surgery | O28: yes | Q28: Id2309 | R28: 2000 | S28: Oct | T28: 9 | U28: 0 | V28: 1012 | W28: tier - 3 | X28: tier - 2 | Y28: R1013
H29: Id28 | I29: 36.86 | J29: 5.19 | K29: yes | L29: No | M29: Yes | N29: 1 | O29: yes | Q29: Id2308 | R29: 1999 | S29: Aug | T29: 5 | U29: 0 | V29: 1019 | W29: tier - 3 | X29: tier - 2 | Y29: R1013
H30: Id29 | I30: 35.86 | J30: 6.74 | K30: yes | L30: No | M30: No | N30: 2 | O30: yes | Q30: Id2307 | R30: 1995 | S30: Oct | T30: 5 | U30: 0 | V30: 1033.74 | W30: tier - 3 | X30: tier - 1 | Y30: R1013
H31: Id30 | I31: 37.05 | J31: 8.44 | K31: No | L31: No | M31: No | N31: No major surgery | O31: yes | Q31: Id2306 | R31: 1994 | S31: Nov | T31: 17 | U31: 0 | V31: 1044 | W31: tier - 3 | X31: tier - 2 | Y31: R1013
H32: Id31 | I32: 43.89 | J32: 8.71 | K32: No | L32: No | M32: No | N32: No major surgery | O32: yes | Q32: Id2305 | R32: 2002 | S32: Jul | T32: 20 | U32: 0 | V32: 1047 | W32: tier - 3 | X32: tier - 1 | Y32: R1013
H33: Id32 | I33: 42.35 | J33: 5.08 | K33: yes | L33: No | M33: No | N33: No major surgery | O33: yes | Q33: Id2304 | R33: 2002 | S33: Jul | T33: 1 | U33: 0 | V33: 1049 | W33: tier - 3 | X33: tier - 2 | Y33: R1012
H34: Id33 | I34: 31.35 | J34: 6.86 | K34: No | L34: No | M34: No | N34: No major surgery | O34: yes | Q34: Id2303 | R34: 1995 | S34: Jun | T34: 1 | U34: 0 | V34: 1056 | W34: tier - 3 | X34: tier - 2 | Y34: R1013
H35: Id34 | I35: 47.6 | J35: 5.95 | K35: yes | L35: No | M35: No | N35: No major surgery | O35: yes | Q35: Id2302 | R35: 1993 | S35: Sep | T35: 28 | U35: 0 | V35: 1068 | W35: tier - 3 | X35: tier - 1 | Y35: R1013
H36: Id35 | I36: 46.2 | J36: 6.09 | K36: No | L36: No | M36: Yes | N36: 1 | O36: yes | Q36: Id2301 | R36: 2004 | S36: Aug | T36: 24 | U36: 0 | V36: 1070 | W36: tier - 3 | X36: tier - 3 | Y36: R1013
H37: Id36 | I37: 32.015 | J37: 11.75 | K37: No | L37: No | M37: No | N37: No major surgery | O37: yes | Q37: Id2300 | R37: 1997 | S37: Aug | T37: 13 | U37: 0 | V37: 1071 | W37: tier - 3 | X37: tier - 3 | Y37: R1013
H38: Id37 | I38: 40.565 | J38: 7.37 | K38: No | L38: No | M38: No | N38: No major surgery | O38: yes | Q38: Id2299 | R38: 1998 | S38: Dec | T38: 26 | U38: 0 | V38: 1082 | W38: tier - 3 | X38: tier - 2 | Y38: R1013
H39: Id38 | I39: 32.45 | J39: 11.91 | K39: No | L39: No | M39: No | N39: No major surgery | O39: yes | Q39: Id2298 | R39: 2002 | S39: Aug | T39: 13 | U39: 0 | V39: 1086 | W39: tier - 3 | X39: tier - 3 | Y39: R1013
H40: Id39 | I40: 34.96 | J40: 6.52 | K40: No | L40: No | M40: No | N40: No major surgery | O40: yes | Q40: Id2297 | R40: 2004 | S40: Nov | T40: 12 | U40: 0 | V40: 1121.87 | W40: tier - 3 | X40: tier - 1 | Y40: R1013
...

Sheet DATA CLEANING 2
A1: Customer ID | B1: year | C1: month
A2: Id2335 | B2: 1992 | C2: Jul
A3: Id2334 | B3: 1992 | C3: Nov
A4: Id2333 | B4: 1993 | C4: Jun
A5: Id2332 | B5: 1992 | C5: Sep | D5: AVERAGE | E5: =AVERAGEIF(B:B,"<>?",B:B) -> 1982.8417
A6: Id2331 | B6: 1998 | C6: Jul
A7: Id2330 | B7: 2001 | C7: Nov
A8: Id2329 | B8: 1993 | C8: Jun
A9: Id2328 | B9: 1995 | C9: Jul
A10: Id2327 | B10: 2002 | C10: Nov
A11: Id2326 | B11: 1997 | C11: Nov
A12: Id2325 | B12: 2001 | C12: Sep
A13: Id2324 | B13: 1999 | C13: Dec
A14: Id2323 | B14: 1999 | C14: Dec
A15: Id2322 | B15: 2002 | C15: Sep
A16: Id2321 | B16: 1993 | C16: Aug
A17: Id2320 | B17: 1996 | C17: Oct
... A2344: Id1 | B2344: 1968 | C2344: Oct

Sheet DATA CLEANING 3
A1: Customer ID | B1: smoker | C1: Hospital tier | D1: City tier | F1: Smoker:
A2: Id1 | B2: yes | C2: tier - 2 | D2: tier - 3 | F2: yes | G2: =COUNTIF(B:B, "yes") -> 488
A3: Id2 | B3: yes | C3: tier - 2 | D3: tier - 1 | F3: No | G3: =COUNTIF(B:B,"No") -> 1847
A4: Id3 | B4: yes | C4: tier - 2 | D4: tier - 1 | F4: Hospital tier:
A5: Id4 | B5: yes | C5: tier - 3 | D5: tier - 3 | F5: tier - 1 | G5: =COUNTIF(C:C,"tier - 1") -> 309
A6: Id5 | B6: yes | C6: tier - 3 | D6: tier - 3 | F6: tier - 2 | G6: =COUNTIF(C:C,"tier - 2") -> 1340
A7: Id6 | B7: yes | C7: tier - 3 | D7: tier - 3 | F7: tier - 3 | G7: =COUNTIF(C:C,"tier - 3") -> 694
A8: Id7 | B8: yes | C8: tier - 3 | D8: tier - 3 | F8: City tier:
A9: Id8 | B9: yes | C9: tier - 3 | D9: tier - 3 | F9: tier - 1 | G9: =COUNTIF(D:D,"tier - 1") -> 734
A10: Id9 | B10: yes | C10: tier - 3 | D10: tier - 2 | F10: tier - 2 | G10: =COUNTIF(D:D,"tier - 2") -> 813
A11: Id10 | B11: yes | C11: tier - 3 | D11: tier - 3 | F11: tier - 3 | G11: =COUNTIF(D:D,"tier - 3") -> 796
A12: Id11 | B12: yes | C12: tier - 3 | D12: tier - 2
A13: Id12 | B13: yes | C13: tier - 2 | D13: tier - 3
A14: Id13 | B14: yes | C14: tier - 3 | D14: tier - 1
A15: Id14 | B15: yes | C15: tier - 3 | D15: tier - 1
A16: Id15 | B16: yes | C16: tier - 3 | D16: tier - 1
A17: Id16 | B17: yes | C17: tier - 3 | D17: tier - 3
A18: Id17 | B18: yes | C18: tier - 3 | D18: tier - 3
A19: Id18 | B19: yes | C19: tier - 3 | D19: tier - 2
A20: Id19 | B20: yes | C20: tier - 3 | D20: tier - 2
A21: Id20 | B21: yes | C21: tier - 3 | D21: tier - 2
A22: Id21 | B22: yes | C22: tier - 3 | D22: tier - 1
A23: Id22 | B23: yes | C23: tier - 3 | D23: tier - 1
... A2336: Id2335 | B2336: No | C2336: tier - 1 | D2336: tier - 2
C2337: tier - 2 | D2337: tier - 2
C2338: tier - 1 | D2338: tier - 3
C2339: tier - 1 | D2339: tier - 3
C2340: tier - 1 | D2340: tier - 2
C2341: tier - 1 | D2341: tier - 3
C2342: tier - 1 | D2342: tier - 1
C2343: tier - 2 | D2343: tier - 3
C2344: tier - 1 | D2344: tier - 3

Sheet DATA CLEANING 4
A1: Customer ID | B1: State ID
A2: Id1 | B2: R1013
A3: Id2 | B3: R1013
A4: Id3 | B4: R1013
A5: Id4 | B5: R1013
A6: Id5 | B6: R1013 | C6: Missing values: | D6: =COUNTIF(B:B,"UNKNOWN") -> 2
A7: Id6 | B7: R1012
A8: Id7 | B8: R1013
A9: Id8 | B9: R1013
A10: Id9 | B10: R1012
A11: Id10 | B11: R1013
A12: Id11 | B12: R1013
A13: Id12 | B13: R1013
A14: Id13 | B14: R1013
A15: Id14 | B15: R1012
A16: Id15 | B16: R1013
A17: Id16 | B17: R1013
A18: Id17 | B18: R1013
... A2336: Id2335 | B2336: R1013
B2337: R1013
B2338: R1011
B2339: R1011
B2340: R1012
B2341: R1024
B2342: R1012
B2343: R1013
B2344: R1013

Sheet DATA TRANSFORMATION 1
A1: Customer ID | B1: name | C1: TITLE | D1: FIRST NAME | E1: LAST NAME
A2: Id1 | B2: Hawks, Ms. Kelly | C2: Ms | D2: Hawks | E2: Kelly
A3: Id2 | B3: Lehner, Mr. Matthew D | C3: Mr | D3: Lehner | E3: Matthew D
A4: Id3 | B4: Lu, Mr. Phil | C4: Mr | D4: Lu | E4: Phil
A5: Id4 | B5: Osborne, Ms. Kelsey | C5: Ms | D5: Osborne | E5: Kelsey
A6: Id5 | B6: Kadala, Ms. Kristyn | C6: Ms | D6: Kadala | E6: Kristyn
A7: Id6 | B7: Baker, Mr. Russell B. | C7: Mr | D7: Baker | E7: Russell B
A8: Id7 | B8: Macpherson, Mr. Scott | C8: Mr | D8: Macpherson | E8: Scott
A9: Id8 | B9: Hallman, Mr. Stephen | C9: Mr | D9: Hallman | E9: Stephen
A10: Id9 | B10: Moran, Mr. Patrick R. | C10: Mr | D10: Moran | E10: Patrick R
A11: Id10 | B11: Benner, Ms. Brooke N. | C11: Ms | D11: Benner | E11: Brooke N
A12: Id11 | B12: Fierro Vargas, Ms. Paola Andrea | C12: Ms | D12: Fierro Vargas | E12: Paola Andrea
... A2336: Id2335 | B2336: German, Mr. Aaron K | C2336: Mr | D2336: German | E2336: Aaron K

Sheet DATA TRANSFORMATION 2
A1: Customer ID | B1: NumberOfMajorSurgeries
A2: Id1 | B2: 0
A3: Id2 | B3: 0
A4: Id3 | B4: 2
A5: Id4 | B5: 0
A6: Id5 | B6: 0
A7: Id6 | B7: 0
A8: Id7 | B8: 0
A9: Id8 | B9: 3
A10: Id9 | B10: 1
A11: Id10 | B11: 0
A12: Id11 | B12: 2
A13: Id12 | B13: 0
... A2336: Id2335 | B2336: 1

Sheet DATA TRANSFORMATION 3
A1: Customer ID | B1: Heart Issues | C1: smoker
A2: Id1 | B2: No | C2: Yes
A3: Id2 | B3: No | C3: Yes
A4: Id3 | B4: Yes | C4: Yes
A5: Id4 | B5: No | C5: Yes
A6: Id5 | B6: No | C6: Yes
A7: Id6 | B7: No | C7: Yes
A8: Id7 | B8: No | C8: Yes
A9: Id8 | B9: No | C9: Yes
A10: Id9 | B10: Yes | C10: Yes
A11: Id10 | B11: No | C11: Yes
A12: Id11 | B12: Yes | C12: Yes
... A2336: Id2335 | B2336: No | C2336: No

Sheet DATA TRANSFORMATION 4
A1: Customer ID | B1: BMI | C1: Weight Status
A2: Id1 | B2: 47.41 | C2: =IF(B2<18.5,"Under Weight",IF(B2<25,"Normal Weight",IF(B2<30,"Over Weight","Obesity"))) -> Obesity
A3: Id2 | B3: 30.36 | C3: =IF(B3<18.5,"Under Weight",IF(B3<25,"Normal Weight",IF(B3<30,"Over Weight","Obesity"))) -> Obesity
A4: Id3 | B4: 34.485 | C4: =IF(B4<18.5,"Under Weight",IF(B4<25,"Normal Weight",IF(B4<30,"Over Weight","Obesity"))) -> Obesity
A5: Id4 | B5: 38.095 | C5: =IF(B5<18.5,"Under Weight",IF(B5<25,"Normal Weight",IF(B5<30,"Over Weight","Obesity"))) -> Obesity
A6: Id5 | B6: 35.53 | C6: =IF(B6<18.5,"Under Weight",IF(B6<25,"Normal Weight",IF(B6<30,"Over Weight","Obesity"))) -> Obesity
A7: Id6 | B7: 32.8 | C7: =IF(B7<18.5,"Under Weight",IF(B7<25,"Normal Weight",IF(B7<30,"Over Weight","Obesity"))) -> Obesity
A8: Id7 | B8: 36.4 | C8: =IF(B8<18.5,"Under Weight",IF(B8<25,"Normal Weight",IF(B8<30,"Over Weight","Obesity"))) -> Obesity
A9: Id8 | B9: 36.96 | C9: =IF(B9<18.5,"Under Weight",IF(B9<25,"Normal Weight",IF(B9<30,"Over Weight","Obesity"))) -> Obesity
A10: Id9 | B10: 41.14 | C10: =IF(B10<18.5,"Under Weight",IF(B10<25,"Normal Weight",IF(B10<30,"Over Weight","Obesity"))) -> Obesity
A11: Id10 | B11: 38.06 | C11: =IF(B11<18.5,"Under Weight",IF(B11<25,"Normal Weight",IF(B11<30,"Over Weight","Obesity"))) -> Obesity
A12: Id11 | B12: 37.7 | C12: =IF(B12<18.5,"Under Weight",IF(B12<25,"Normal Weight",IF(B12<30,"Over Weight","Obesity"))) -> Obesity
A13: Id12 | B13: 42.13 | C13: =IF(B13<18.5,"Under Weight",IF(B13<25,"Normal Weight",IF(B13<30,"Over Weight","Obesity"))) -> Obesity
... A2336: Id2335 | B2336: 17.58 | C2336: =IF(B2336<18.5,"Under Weight",IF(B2336<25,"Normal Weight",IF(B2336<30,"Over Weight","Obesity"))) -> Under Weight

Sheet DATA TRANSFORMATION 5
A1: Customer ID | B1: HBA1C | C1: Diabetes Status
A2: Id1 | B2: 7.47 | C2: =IF(B2<5.7,"Normal",IF(B2<6.5,"Prediabetes","Diabetes")) -> Diabetes
A3: Id2 | B3: 5.77 | C3: =IF(B3<5.7,"Normal",IF(B3<6.5,"Prediabetes","Diabetes")) -> Prediabetes
A4: Id3 | B4: 11.87 | C4: =IF(B4<5.7,"Normal",IF(B4<6.5,"Prediabetes","Diabetes")) -> Diabetes
A5: Id4 | B5: 6.05 | C5: =IF(B5<5.7,"Normal",IF(B5<6.5,"Prediabetes","Diabetes")) -> Prediabetes
A6: Id5 | B6: 5.45 | C6: =IF(B6<5.7,"Normal",IF(B6<6.5,"Prediabetes","Diabetes")) -> Normal
A7: Id6 | B7: 6.59 | C7: =IF(B7<5.7,"Normal",IF(B7<6.5,"Prediabetes","Diabetes")) -> Diabetes
A8: Id7 | B8: 6.07 | C8: =IF(B8<5.7,"Normal",IF(B8<6.5,"Prediabetes","Diabetes")) -> Prediabetes
A9: Id8 | B9: 7.93 | C9: =IF(B9<5.7,"Normal",IF(B9<6.5,"Prediabetes","Diabetes")) -> Diabetes
A10: Id9 | B10: 9.58 | C10: =IF(B10<5.7,"Normal",IF(B10<6.5,"Prediabetes","Diabetes")) -> Diabetes
A11: Id10 | B11: 10.79 | C11: =IF(B11<5.7,"Normal",IF(B11<6.5,"Prediabetes","Diabetes")) -> Diabetes
A12: Id11 | B12: 5.96 | C12: =IF(B12<5.7,"Normal",IF(B12<6.5,"Prediabetes","Diabetes")) -> Prediabetes
A13: Id12 | B13: 11.9 | C13: =IF(B13<5.7,"Normal",IF(B13<6.5,"Prediabetes","Diabetes")) -> Diabetes
... A2336: Id2335 | B2336: 4.51 | C2336: =IF(B2336<5.7,"Normal",IF(B2336<6.5,"Prediabetes","Diabetes")) -> Normal

Sheet DATA TRANSFORMATION 6
A1: Customer ID | B1: date | C1: month | D1: year | E1: Date Of Birth
A2: Id1 | B2: 9 | C2: Jul | D2: 1992 | E2: =CONCATENATE(B2,"-",C2,"-",D2) -> 9-Jul-1992
A3: Id2 | B3: 30 | C3: Nov | D3: 1992 | E3: =CONCATENATE(B3,"-",C3,"-",D3) -> 30-Nov-1992
A4: Id3 | B4: 30 | C4: Jun | D4: 1993 | E4: =CONCATENATE(B4,"-",C4,"-",D4) -> 30-Jun-1993
A5: Id4 | B5: 13 | C5: Sep | D5: 1992 | E5: =CONCATENATE(B5,"-",C5,"-",D5) -> 13-Sep-1992
A6: Id5 | B6: 27 | C6: Jul | D6: 1998 | E6: =CONCATENATE(B6,"-",C6,"-",D6) -> 27-Jul-1998
A7: Id6 | B7: 20 | C7: Nov | D7: 2001 | E7: =CONCATENATE(B7,"-",C7,"-",D7) -> 20-Nov-2001
A8: Id7 | B8: 1 | C8: Jun | D8: 1993 | E8: =CONCATENATE(B8,"-",C8,"-",D8) -> 1-Jun-1993
A9: Id8 | B9: 4 | C9: Jul | D9: 1995 | E9: =CONCATENATE(B9,"-",C9,"-",D9) -> 4-Jul-1995
A10: Id9 | B10: 29 | C10: Nov | D10: 2002 | E10: =CONCATENATE(B10,"-",C10,"-",D10) -> 29-Nov-2002
A11: Id10 | B11: 9 | C11: Nov | D11: 1997 | E11: =CONCATENATE(B11,"-",C11,"-",D11) -> 9-Nov-1997
A12: Id11 | B12: 12 | C12: Sep | D12: 2001 | E12: =CONCATENATE(B12,"-",C12,"-",D12) -> 12-Sep-2001
A13: Id12 | B13: 26 | C13: Dec | D13: 1999 | E13: =CONCATENATE(B13,"-",C13,"-",D13) -> 26-Dec-1999
... A2336: Id2335 | B2336: 4 | C2336: Sep | D2336: 1963 | E2336: =CONCATENATE(B2336,"-",C2336,"-",D2336) -> 4-Sep-1963
B2337: 27 | C2337: Jun | D2337: 1958 | E2337: =CONCATENATE(B2337,"-",C2337,"-",D2337) -> 27-Jun-1958
B2338: 27 | C2338: Oct | D2338: 1994 | E2338: =CONCATENATE(B2338,"-",C2338,"-",D2338) -> 27-Oct-1994
B2339: 4 | C2339: Aug | D2339: 1962 | E2339: =CONCATENATE(B2339,"-",C2339,"-",D2339) -> 4-Aug-1962
B2340: 19 | C2340: Jun | D2340: 1989 | E2340: =CONCATENATE(B2340,"-",C2340,"-",D2340) -> 19-Jun-1989
B2341: 6 | C2341: Jun | D2341: 1991 | E2341: =CONCATENATE(B2341,"-",C2341,"-",D2341) -> 6-Jun-1991
B2342: 11 | C2342: Sep | D2342: 1970 | E2342: =CONCATENATE(B2342,"-",C2342,"-",D2342) -> 11-Sep-1970
B2343: 8 | C2343: Jun | D2343: 1977 | E2343: =CONCATENATE(B2343,"-",C2343,"-",D2343) -> 8-Jun-1977
B2344: 12 | C2344: Oct | D2344: 1968 | E2344: =CONCATENATE(B2344,"-",C2344,"-",D2344) -> 12-Oct-1968

Sheet DATA TANSFORMATION 7
A1: Customer ID | B1: date | C1: month | D1: year | E1: Date Of Birth | F1: Age
A2: Id1 | B2: 9 | C2: Jul | D2: 1992 | E2: =CONCATENATE(B2,"-",C2,"-",D2) -> 9-Jul-1992 | F2: =DATEDIF(E2,DATE(2023,6,8),"Y") -> 30
A3: Id2 | B3: 30 | C3: Nov | D3: 1992 | E3: =CONCATENATE(B3,"-",C3,"-",D3) -> 30-Nov-1992 | F3: =DATEDIF(E3,DATE(2023,6,8),"Y") -> 30
A4: Id3 | B4: 30 | C4: Jun | D4: 1993 | E4: =CONCATENATE(B4,"-",C4,"-",D4) -> 30-Jun-1993 | F4: =DATEDIF(E4,DATE(2023,6,8),"Y") -> 29
A5: Id4 | B5: 13 | C5: Sep | D5: 1992 | E5: =CONCATENATE(B5,"-",C5,"-",D5) -> 13-Sep-1992 | F5: =DATEDIF(E5,DATE(2023,6,8),"Y") -> 30
A6: Id5 | B6: 27 | C6: Jul | D6: 1998 | E6: =CONCATENATE(B6,"-",C6,"-",D6) -> 27-Jul-1998 | F6: =DATEDIF(E6,DATE(2023,6,8),"Y") -> 24
A7: Id6 | B7: 20 | C7: Nov | D7: 2001 | E7: =CONCATENATE(B7,"-",C7,"-",D7) -> 20-Nov-2001 | F7: =DATEDIF(E7,DATE(2023,6,8),"Y") -> 21
A8: Id7 | B8: 1 | C8: Jun | D8: 1993 | E8: =CONCATENATE(B8,"-",C8,"-",D8) -> 1-Jun-1993 | F8: =DATEDIF(E8,DATE(2023,6,8),"Y") -> 30
A9: Id8 | B9: 4 | C9: Jul | D9: 1995 | E9: =CONCATENATE(B9,"-",C9,"-",D9) -> 4-Jul-1995 | F9: =DATEDIF(E9,DATE(2023,6,8),"Y") -> 27
A10: Id9 | B10: 29 | C10: Nov | D10: 2002 | E10: =CONCATENATE(B10,"-",C10,"-",D10) -> 29-Nov-2002 | F10: =DATEDIF(E10,DATE(2023,6,8),"Y") -> 20
A11: Id10 | B11: 9 | C11: Nov | D11: 1997 | E11: =CONCATENATE(B11,"-",C11,"-",D11) -> 9-Nov-1997 | F11: =DATEDIF(E11,DATE(2023,6,8),"Y") -> 25
A12: Id11 | B12: 12 | C12: Sep | D12: 2001 | E12: =CONCATENATE(B12,"-",C12,"-",D12) -> 12-Sep-2001 | F12: =DATEDIF(E12,DATE(2023,6,8),"Y") -> 21
A13: Id12 | B13: 26 | C13: Dec | D13: 1999 | E13: =CONCATENATE(B13,"-",C13,"-",D13) -> 26-Dec-1999 | F13: =DATEDIF(E13,DATE(2023,6,8),"Y") -> 23
... A2336: Id2335 | B2336: 4 | C2336: Sep | D2336: 1963 | E2336: =CONCATENATE(B2336,"-",C2336,"-",D2336) -> 4-Sep-1963 | F2336: =DATEDIF(E2336,DATE(2023,6,8),"Y") -> 59
B2337: 27 | C2337: Jun | D2337: 1958 | E2337: =CONCATENATE(B2337,"-",C2337,"-",D2337) -> 27-Jun-1958 | F2337: =DATEDIF(E2337,DATE(2023,6,8),"Y") -> 64
B2338: 27 | C2338: Oct | D2338: 1994 | E2338: =CONCATENATE(B2338,"-",C2338,"-",D2338) -> 27-Oct-1994 | F2338: =DATEDIF(E2338,DATE(2023,6,8),"Y") -> 28
B2339: 4 | C2339: Aug | D2339: 1962 | E2339: =CONCATENATE(B2339,"-",C2339,"-",D2339) -> 4-Aug-1962 | F2339: =DATEDIF(E2339,DATE(2023,6,8),"Y") -> 60
B2340: 19 | C2340: Jun | D2340: 1989 | E2340: =CONCATENATE(B2340,"-",C2340,"-",D2340) -> 19-Jun-1989 | F2340: =DATEDIF(E2340,DATE(2023,6,8),"Y") -> 33
B2341: 6 | C2341: Jun | D2341: 1991 | E2341: =CONCATENATE(B2341,"-",C2341,"-",D2341) -> 6-Jun-1991 | F2341: =DATEDIF(E2341,DATE(2023,6,8),"Y") -> 32
B2342: 11 | C2342: Sep | D2342: 1970 | E2342: =CONCATENATE(B2342,"-",C2342,"-",D2342) -> 11-Sep-1970 | F2342: =DATEDIF(E2342,DATE(2023,6,8),"Y") -> 52
B2343: 8 | C2343: Jun | D2343: 1977 | E2343: =CONCATENATE(B2343,"-",C2343,"-",D2343) -> 8-Jun-1977 | F2343: =DATEDIF(E2343,DATE(2023,6,8),"Y") -> 46
B2344: 12 | C2344: Oct | D2344: 1968 | E2344: =CONCATENATE(B2344,"-",C2344,"-",D2344) -> 12-Oct-1968 | F2344: =DATEDIF(E2344,DATE(2023,6,8),"Y") -> 54

Sheet DATA TRANSFORMATION 8
A1: Customer ID | B1: charges
A2: Id1 | B2: 563.84
A3: Id2 | B3: 570.62
A4: Id3 | B4: 600
A5: Id4 | B5: 604.54
A6: Id5 | B6: 637.26
A7: Id6 | B7: 646.14
A8: Id7 | B8: 650
A9: Id8 | B9: 650
A10: Id9 | B10: 668
A11: Id10 | B11: 670
A12: Id11 | B12: 687.54
A13: Id12 | B13: 700
... A2336: Id2335 | B2336: 48970.25
B2337: 49577.66
B2338: 51194.56
B2339: 52590.83
B2340: 55135.4
B2341: 58571.07
B2342: 60021.4
B2343: 62592.87
B2344: 63770.43

Sheet HEALTH CARE
A1: Customer ID | B1: First Name | C1: BMI | D1: HBA1C | E1: Heart Issues | F1: Any Transplants | G1: Cancer History | H1: Number Of Major Surgeries | I1: Smoker | J1: Weight Status | K1: Diabetes Status | L1: Date Of Birth | M1: Charges | N1: Hospital Tier | O1: City Tier | P1: State ID | Q1: Age
A2: Id1 | B2: =VLOOKUP(A2,'DATA TRANSFORMATION 1'!A:E,4,FALSE) -> Hawks | C2: =VLOOKUP(A2,'MEDICAL EXAMINATIONS'!A:H,2,FALSE) -> 47.41 | D2: =VLOOKUP(A2,'MEDICAL EXAMINATIONS'!A:H,3,FALSE) -> 7.47 | E2: =VLOOKUP(A2,'DATA TRANSFORMATION 3'!A:C,2,FALSE) -> No | F2: =VLOOKUP(A2,'MEDICAL EXAMINATIONS'!A:H,5,FALSE) -> No | G2: =VLOOKUP(A2,'MEDICAL EXAMINATIONS'!A:H,6,FALSE) -> No | H2: =VLOOKUP(A2,'DATA TRANSFORMATION 2'!A:B,2,FALSE) -> 0 | I2: =VLOOKUP(A2,'DATA TRANSFORMATION 3'!A:C,3,FALSE) -> Yes | J2: =VLOOKUP(A2,'DATA TRANSFORMATION 4'!A:C,3,FALSE) -> Obesity | K2: =VLOOKUP(A2,'DATA TRANSFORMATION 5'!A:C,3,FALSE) -> Diabetes | L2: =VLOOKUP(A2,'DATA TRANSFORMATION 6'!A:E,5,FALSE) -> 9-Jul-1992 | M2: =VLOOKUP(A2,'DATA TRANSFORMATION 8'!A:B,2,FALSE) -> 563.84 | N2: =VLOOKUP(A2,'DATA CLEANING 3'!A:D,3,FALSE) -> tier - 2 | O2: =VLOOKUP(A2,'DATA CLEANING 3'!A:D,4,FALSE) -> tier - 3 | P2: =VLOOKUP(A2,'DATA CLEANING 4'!A:B,2,FALSE) -> R1013 | Q2: =VLOOKUP(A2,'DATA TANSFORMATION 7'!A:F,6,FALSE) -> 30
A3: Id2 | B3: =VLOOKUP(A3,'DATA TRANSFORMATION 1'!A:E,4,FALSE) -> Lehner | C3: =VLOOKUP(A3,'MEDICAL EXAMINATIONS'!A:H,2,FALSE) -> 30.36 | D3: =VLOOKUP(A3,'MEDICAL EXAMINATIONS'!A:H,3,FALSE) -> 5.77 | E3: =VLOOKUP(A3,'DATA TRANSFORMATION 3'!A:C,2,FALSE) -> No | F3: =VLOOKUP(A3,'MEDICAL EXAMINATIONS'!A:H,5,FALSE) -> No | G3: =VLOOKUP(A3,'MEDICAL EXAMINATIONS'!A:H,6,FALSE) -> No | H3: =VLOOKUP(A3,'DATA TRANSFORMATION 2'!A:B,2,FALSE) -> 0 | I3: =VLOOKUP(A3,'DATA TRANSFORMATION 3'!A:C,3,FALSE) -> Yes | J3: =VLOOKUP(A3,'DATA TRANSFORMATION 4'!A:C,3,FALSE) -> Obesity | K3: =VLOOKUP(A3,'DATA TRANSFORMATION 5'!A:C,3,FALSE) -> Prediabetes | L3: =VLOOKUP(A3,'DATA TRANSFORMATION 6'!A:E,5,FALSE) -> 30-Nov-1992 | M3: =VLOOKUP(A3,'DATA TRANSFORMATION 8'!A:B,2,FALSE) -> 570.62 | N3: =VLOOKUP(A3,'DATA CLEANING 3'!A:D,3,FALSE) -> tier - 2 | O3: =VLOOKUP(A3,'DATA CLEANING 3'!A:D,4,FALSE) -> tier - 1 | P3: =VLOOKUP(A3,'DATA CLEANING 4'!A:B,2,FALSE) -> R1013 | Q3: =VLOOKUP(A3,'DATA TANSFORMATION 7'!A:F,6,FALSE) -> 30
A4: Id3 | B4: =VLOOKUP(A4,'DATA TRANSFORMATION 1'!A:E,4,FALSE) -> Lu | C4: =VLOOKUP(A4,'MEDICAL EXAMINATIONS'!A:H,2,FALSE) -> 34.485 | D4: =VLOOKUP(A4,'MEDICAL EXAMINATIONS'!A:H,3,FALSE) -> 11.87 | E4: =VLOOKUP(A4,'DATA TRANSFORMATION 3'!A:C,2,FALSE) -> Yes | F4: =VLOOKUP(A4,'MEDICAL EXAMINATIONS'!A:H,5,FALSE) -> No | G4: =VLOOKUP(A4,'MEDICAL EXAMINATIONS'!A:H,6,FALSE) -> No | H4: =VLOOKUP(A4,'DATA TRANSFORMATION 2'!A:B,2,FALSE) -> 2 | I4: =VLOOKUP(A4,'DATA TRANSFORMATION 3'!A:C,3,FALSE) -> Yes | J4: =VLOOKUP(A4,'DATA TRANSFORMATION 4'!A:C,3,FALSE) -> Obesity | K4: =VLOOKUP(A4,'DATA TRANSFORMATION 5'!A:C,3,FALSE) -> Diabetes | L4: =VLOOKUP(A4,'DATA TRANSFORMATION 6'!A:E,5,FALSE) -> 30-Jun-1993 | M4: =VLOOKUP(A4,'DATA TRANSFORMATION 8'!A:B,2,FALSE) -> 600 | N4: =VLOOKUP(A4,'DATA CLEANING 3'!A:D,3,FALSE) -> tier - 2 | O4: =VLOOKUP(A4,'DATA CLEANING 3'!A:D,4,FALSE) -> tier - 1 | P4: =VLOOKUP(A4,'DATA CLEANING 4'!A:B,2,FALSE) -> R1013 | Q4: =VLOOKUP(A4,'DATA TANSFORMATION 7'!A:F,6,FALSE) -> 29
A5: Id4 | B5: =VLOOKUP(A5,'DATA TRANSFORMATION 1'!A:E,4,FALSE) -> Osborne | C5: =VLOOKUP(A5,'MEDICAL EXAMINATIONS'!A:H,2,FALSE) -> 38.095 | D5: =VLOOKUP(A5,'MEDICAL EXAMINATIONS'!A:H,3,FALSE) -> 6.05 | E5: =VLOOKUP(A5,'DATA TRANSFORMATION 3'!A:C,2,FALSE) -> No | F5: =VLOOKUP(A5,'MEDICAL EXAMINATIONS'!A:H,5,FALSE) -> No | G5: =VLOOKUP(A5,'MEDICAL EXAMINATIONS'!A:H,6,FALSE) -> No | H5: =VLOOKUP(A5,'DATA TRANSFORMATION 2'!A:B,2,FALSE) -> 0 | I5: =VLOOKUP(A5,'DATA TRANSFORMATION 3'!A:C,3,FALSE) -> Yes | J5: =VLOOKUP(A5,'DATA TRANSFORMATION 4'!A:C,3,FALSE) -> Obesity | K5: =VLOOKUP(A5,'DATA TRANSFORMATION 5'!A:C,3,FALSE) -> Prediabetes | L5: =VLOOKUP(A5,'DATA TRANSFORMATION 6'!A:E,5,FALSE) -> 13-Sep-1992 | M5: =VLOOKUP(A5,'DATA TRANSFORMATION 8'!A:B,2,FALSE) -> 604.54 | N5: =VLOOKUP(A5,'DATA CLEANING 3'!A:D,3,FALSE) -> tier - 3 | O5: =VLOOKUP(A5,'DATA CLEANING 3'!A:D,4,FALSE) -> tier - 3 | P5: =VLOOKUP(A5,'DATA CLEANING 4'!A:B,2,FALSE) -> R1013 | Q5: =VLOOKUP(A5,'DATA TANSFORMATION 7'!A:F,6,FALSE) -> 30
A6: Id5 | B6: =VLOOKUP(A6,'DATA TRANSFORMATION 1'!A:E,4,FALSE) -> Kadala | C6: =VLOOKUP(A6,'MEDICAL EXAMINATIONS'!A:H,2,FALSE) -> 35.53 | D6: =VLOOKUP(A6,'MEDICAL EXAMINATIONS'!A:H,3,FALSE) -> 5.45 | E6: =VLOOKUP(A6,'DATA TRANSFORMATION 3'!A:C,2,FALSE) -> No | F6: =VLOOKUP(A6,'MEDICAL EXAMINATIONS'!A:H,5,FALSE) -> No | G6: =VLOOKUP(A6,'MEDICAL EXAMINATIONS'!A:H,6,FALSE) -> No | H6: =VLOOKUP(A6,'DATA TRANSFORMATION 2'!A:B,2,FALSE) -> 0 | I6: =VLOOKUP(A6,'DATA TRANSFORMATION 3'!A:C,3,FALSE) -> Yes | J6: =VLOOKUP(A6,'DATA TRANSFORMATION 4'!A:C,3,FALSE) -> Obesity | K6: =VLOOKUP(A6,'DATA TRANSFORMATION 5'!A:C,3,FALSE) -> Normal | L6: =VLOOKUP(A6,'DATA TRANSFORMATION 6'!A:E,5,FALSE) -> 27-Jul-1998 | M6: =VLOOKUP(A6,'DATA TRANSFORMATION 8'!A:B,2,FALSE) -> 637.26 | N6: =VLOOKUP(A6,'DATA CLEANING 3'!A:D,3,FALSE) -> tier - 3 | O6: =VLOOKUP(A6,'DATA CLEANING 3'!A:D,4,FALSE) -> tier - 3 | P6: =VLOOKUP(A6,'DATA CLEANING 4'!A:B,2,FALSE) -> R1013 | Q6: =VLOOKUP(A6,'DATA TANSFORMATION 7'!A:F,6,FALSE) -> 24
A7: Id6 | B7: =VLOOKUP(A7,'DATA TRANSFORMATION 1'!A:E,4,FALSE) -> Baker | C7: =VLOOKUP(A7,'MEDICAL EXAMINATIONS'!A:H,2,FALSE) -> 32.8 | D7: =VLOOKUP(A7,'MEDICAL EXAMINATIONS'!A:H,3,FALSE) -> 6.59 | E7: =VLOOKUP(A7,'DATA TRANSFORMATION 3'!A:C,2,FALSE) -> No | F7: =VLOOKUP(A7,'MEDICAL EXAMINATIONS'!A:H,5,FALSE) -> No | G7: =VLOOKUP(A7,'MEDICAL EXAMINATIONS'!A:H,6,FALSE) -> No | H7: =VLOOKUP(A7,'DATA TRANSFORMATION 2'!A:B,2,FALSE) -> 0 | I7: =VLOOKUP(A7,'DATA TRANSFORMATION 3'!A:C,3,FALSE) -> Yes | J7: =VLOOKUP(A7,'DATA TRANSFORMATION 4'!A:C,3,FALSE) -> Obesity | K7: =VLOOKUP(A7,'DATA TRANSFORMATION 5'!A:C,3,FALSE) -> Diabetes | L7: =VLOOKUP(A7,'DATA TRANSFORMATION 6'!A:E,5,FALSE) -> 20-Nov-2001 | M7: =VLOOKUP(A7,'DATA TRANSFORMATION 8'!A:B,2,FALSE) -> 646.14 | N7: =VLOOKUP(A7,'DATA CLEANING 3'!A:D,3,FALSE) -> tier - 3 | O7: =VLOOKUP(A7,'DATA CLEANING 3'!A:D,4,FALSE) -> tier - 3 | P7: =VLOOKUP(A7,'DATA CLEANING 4'!A:B,2,FALSE) -> R1012 | Q7: =VLOOKUP(A7,'DATA TANSFORMATION 7'!A:F,6,FALSE) -> 21
A8: Id7 | B8: =VLOOKUP(A8,'DATA TRANSFORMATION 1'!A:E,4,FALSE) -> Macpherson | C8: =VLOOKUP(A8,'MEDICAL EXAMINATIONS'!A:H,2,FALSE) -> 36.4 | D8: =VLOOKUP(A8,'MEDICAL EXAMINATIONS'!A:H,3,FALSE) -> 6.07 | E8: =VLOOKUP(A8,'DATA TRANSFORMATION 3'!A:C,2,FALSE) -> No | F8: =VLOOKUP(A8,'MEDICAL EXAMINATIONS'!A:H,5,FALSE) -> No | G8: =VLOOKUP(A8,'MEDICAL EXAMINATIONS'!A:H,6,FALSE) -> No | H8: =VLOOKUP(A8,'DATA TRANSFORMATION 2'!A:B,2,FALSE) -> 0 | I8: =VLOOKUP(A8,'DATA TRANSFORMATION 3'!A:C,3,FALSE) -> Yes | J8: =VLOOKUP(A8,'DATA TRANSFORMATION 4'!A:C,3,FALSE) -> Obesity | K8: =VLOOKUP(A8,'DATA TRANSFORMATION 5'!A:C,3,FALSE) -> Prediabetes | L8: =VLOOKUP(A8,'DATA TRANSFORMATION 6'!A:E,5,FALSE) -> 1-Jun-1993 | M8: =VLOOKUP(A8,'DATA TRANSFORMATION 8'!A:B,2,FALSE) -> 650 | N8: =VLOOKUP(A8,'DATA CLEANING 3'!A:D,3,FALSE) -> tier - 3 | O8: =VLOOKUP(A8,'DATA CLEANING 3'!A:D,4,FALSE) -> tier - 3 | P8: =VLOOKUP(A8,'DATA CLEANING 4'!A:B,2,FALSE) -> R1013 | Q8: =VLOOKUP(A8,'DATA TANSFORMATION 7'!A:F,6,FALSE) -> 30
A9: Id8 | B9: =VLOOKUP(A9,'DATA TRANSFORMATION 1'!A:E,4,FALSE) -> Hallman | C9: =VLOOKUP(A9,'MEDICAL EXAMINATIONS'!A:H,2,FALSE) -> 36.96 | D9: =VLOOKUP(A9,'MEDICAL EXAMINATIONS'!A:H,3,FALSE) -> 7.93 | E9: =VLOOKUP(A9,'DATA TRANSFORMATION 3'!A:C,2,FALSE) -> No | F9: =VLOOKUP(A9,'MEDICAL EXAMINATIONS'!A:H,5,FALSE) -> No | G9: =VLOOKUP(A9,'MEDICAL EXAMINATIONS'!A:H,6,FALSE) -> No | H9: =VLOOKUP(A9,'DATA TRANSFORMATION 2'!A:B,2,FALSE) -> 3 | I9: =VLOOKUP(A9,'DATA TRANSFORMATION 3'!A:C,3,FALSE) -> Yes | J9: =VLOOKUP(A9,'DATA TRANSFORMATION 4'!A:C,3,FALSE) -> Obesity | K9: =VLOOKUP(A9,'DATA TRANSFORMATION 5'!A:C,3,FALSE) -> Diabetes | L9: =VLOOKUP(A9,'DATA TRANSFORMATION 6'!A:E,5,FALSE) -> 4-Jul-1995 | M9: =VLOOKUP(A9,'DATA TRANSFORMATION 8'!A:B,2,FALSE) -> 650 | N9: =VLOOKUP(A9,'DATA CLEANING 3'!A:D,3,FALSE) -> tier - 3 | O9: =VLOOKUP(A9,'DATA CLEANING 3'!A:D,4,FALSE) -> tier - 3 | P9: =VLOOKUP(A9,'DATA CLEANING 4'!A:B,2,FALSE) -> R1013 | Q9: =VLOOKUP(A9,'DATA TANSFORMATION 7'!A:F,6,FALSE) -> 27
A10: Id9 | B10: =VLOOKUP(A10,'DATA TRANSFORMATION 1'!A:E,4,FALSE) -> Moran | C10: =VLOOKUP(A10,'MEDICAL EXAMINATIONS'!A:H,2,FALSE) -> 41.14 | D10: =VLOOKUP(A10,'MEDICAL EXAMINATIONS'!A:H,3,FALSE) -> 9.58 | E10: =VLOOKUP(A10,'DATA TRANSFORMATION 3'!A:C,2,FALSE) -> Yes | F10: =VLOOKUP(A10,'MEDICAL EXAMINATIONS'!A:H,5,FALSE) -> No | G10: =VLOOKUP(A10,'MEDICAL EXAMINATIONS'!A:H,6,FALSE) -> Yes | H10: =VLOOKUP(A10,'DATA TRANSFORMATION 2'!A:B,2,FALSE) -> 1 | I10: =VLOOKUP(A10,'DATA TRANSFORMATION 3'!A:C,3,FALSE) -> Yes | J10: =VLOOKUP(A10,'DATA TRANSFORMATION 4'!A:C,3,FALSE) -> Obesity | K10: =VLOOKUP(A10,'DATA TRANSFORMATION 5'!A:C,3,FALSE) -> Diabetes | L10: =VLOOKUP(A10,'DATA TRANSFORMATION 6'!A:E,5,FALSE) -> 29-Nov-2002 | M10: =VLOOKUP(A10,'DATA TRANSFORMATION 8'!A:B,2,FALSE) -> 668 | N10: =VLOOKUP(A10,'DATA CLEANING 3'!A:D,3,FALSE) -> tier - 3 | O10: =VLOOKUP(A10,'DATA CLEANING 3'!A:D,4,FALSE) -> tier - 2 | P10: =VLOOKUP(A10,'DATA CLEANING 4'!A:B,2,FALSE) -> R1012 | Q10: =VLOOKUP(A10,'DATA TANSFORMATION 7'!A:F,6,FALSE) -> 20
A11: Id10 | B11: =VLOOKUP(A11,'DATA TRANSFORMATION 1'!A:E,4,FALSE) -> Benner | C11: =VLOOKUP(A11,'MEDICAL EXAMINATIONS'!A:H,2,FALSE) -> 38.06 | D11: =VLOOKUP(A11,'MEDICAL EXAMINATIONS'!A:H,3,FALSE) -> 10.79 | E11: =VLOOKUP(A11,'DATA TRANSFORMATION 3'!A:C,2,FALSE) -> No | F11: =VLOOKUP(A11,'MEDICAL EXAMINATIONS'!A:H,5,FALSE) -> No | G11: =VLOOKUP(A11,'MEDICAL EXAMINATIONS'!A:H,6,FALSE) -> No | H11: =VLOOKUP(A11,'DATA TRANSFORMATION 2'!A:B,2,FALSE) -> 0 | I11: =VLOOKUP(A11,'DATA TRANSFORMATION 3'!A:C,3,FALSE) -> Yes | J11: =VLOOKUP(A11,'DATA TRANSFORMATION 4'!A:C,3,FALSE) -> Obesity | K11: =VLOOKUP(A11,'DATA TRANSFORMATION 5'!A:C,3,FALSE) -> Diabetes | L11: =VLOOKUP(A11,'DATA TRANSFORMATION 6'!A:E,5,FALSE) -> 9-Nov-1997 | M11: =VLOOKUP(A11,'DATA TRANSFORMATION 8'!A:B,2,FALSE) -> 670 | N11: =VLOOKUP(A11,'DATA CLEANING 3'!A:D,3,FALSE) -> tier - 3 | O11: =VLOOKUP(A11,'DATA CLEANING 3'!A:D,4,FALSE) -> tier - 3 | P11: =VLOOKUP(A11,'DATA CLEANING 4'!A:B,2,FALSE) -> R1013 | Q11: =VLOOKUP(A11,'DATA TANSFORMATION 7'!A:F,6,FALSE) -> 25
A12: Id11 | B12: =VLOOKUP(A12,'DATA TRANSFORMATION 1'!A:E,4,FALSE) -> Fierro Vargas | C12: =VLOOKUP(A12,'MEDICAL EXAMINATIONS'!A:H,2,FALSE) -> 37.7 | D12: =VLOOKUP(A12,'MEDICAL EXAMINATIONS'!A:H,3,FALSE) -> 5.96 | E12: =VLOOKUP(A12,'DATA TRANSFORMATION 3'!A:C,2,FALSE) -> Yes | F12: =VLOOKUP(A12,'MEDICAL EXAMINATIONS'!A:H,5,FALSE) -> No | G12: =VLOOKUP(A12,'MEDICAL EXAMINATIONS'!A:H,6,FALSE) -> No | H12: =VLOOKUP(A12,'DATA TRANSFORMATION 2'!A:B,2,FALSE) -> 2 | I12: =VLOOKUP(A12,'DATA TRANSFORMATION 3'!A:C,3,FALSE) -> Yes | J12: =VLOOKUP(A12,'DATA TRANSFORMATION 4'!A:C,3,FALSE) -> Obesity | K12: =VLOOKUP(A12,'DATA TRANSFORMATION 5'!A:C,3,FALSE) -> Prediabetes | L12: =VLOOKUP(A12,'DATA TRANSFORMATION 6'!A:E,5,FALSE) -> 12-Sep-2001 | M12: =VLOOKUP(A12,'DATA TRANSFORMATION 8'!A:B,2,FALSE) -> 687.54 | N12: =VLOOKUP(A12,'DATA CLEANING 3'!A:D,3,FALSE) -> tier - 3 | O12: =VLOOKUP(A12,'DATA CLEANING 3'!A:D,4,FALSE) -> tier - 2 | P12: =VLOOKUP(A12,'DATA CLEANING 4'!A:B,2,FALSE) -> R1013 | Q12: =VLOOKUP(A12,'DATA TANSFORMATION 7'!A:F,6,FALSE) -> 21
A13: Id12 | B13: =VLOOKUP(A13,'DATA TRANSFORMATION 1'!A:E,4,FALSE) -> Franz | C13: =VLOOKUP(A13,'MEDICAL EXAMINATIONS'!A:H,2,FALSE) -> 42.13 | D13: =VLOOKUP(A13,'MEDICAL EXAMINATIONS'!A:H,3,FALSE) -> 11.9 | E13: =VLOOKUP(A13,'DATA TRANSFORMATION 3'!A:C,2,FALSE) -> No | F13: =VLOOKUP(A13,'MEDICAL EXAMINATIONS'!A:H,5,FALSE) -> No | G13: =VLOOKUP(A13,'MEDICAL EXAMINATIONS'!A:H,6,FALSE) -> No | H13: =VLOOKUP(A13,'DATA TRANSFORMATION 2'!A:B,2,FALSE) -> 0 | I13: =VLOOKUP(A13,'DATA TRANSFORMATION 3'!A:C,3,FALSE) -> Yes | J13: =VLOOKUP(A13,'DATA TRANSFORMATION 4'!A:C,3,FALSE) -> Obesity | K13: =VLOOKUP(A13,'DATA TRANSFORMATION 5'!A:C,3,FALSE) -> Diabetes | L13: =VLOOKUP(A13,'DATA TRANSFORMATION 6'!A:E,5,FALSE) -> 26-Dec-1999 | M13: =VLOOKUP(A13,'DATA TRANSFORMATION 8'!A:B,2,FALSE) -> 700 | N13: =VLOOKUP(A13,'DATA CLEANING 3'!A:D,3,FALSE) -> tier - 2 | O13: =VLOOKUP(A13,'DATA CLEANING 3'!A:D,4,FALSE) -> tier - 3 | P13: =VLOOKUP(A13,'DATA CLEANING 4'!A:B,2,FALSE) -> R1013 | Q13: =VLOOKUP(A13,'DATA TANSFORMATION 7'!A:F,6,FALSE) -> 23
... A2336: Id2335 | B2336: =VLOOKUP(A2336,'DATA TRANSFORMATION 1'!A:E,4,FALSE) -> German | C2336: =VLOOKUP(A2336,'MEDICAL EXAMINATIONS'!A:H,2,FALSE) -> 17.58 | D2336: =VLOOKUP(A2336,'MEDICAL EXAMINATIONS'!A:H,3,FALSE) -> 4.51 | E2336: =VLOOKUP(A2336,'DATA TRANSFORMATION 3'!A:C,2,FALSE) -> No | F2336: =VLOOKUP(A2336,'MEDICAL EXAMINATIONS'!A:H,5,FALSE) -> No | G2336: =VLOOKUP(A2336,'MEDICAL EXAMINATIONS'!A:H,6,FALSE) -> No | H2336: =VLOOKUP(A2336,'DATA TRANSFORMATION 2'!A:B,2,FALSE) -> 1 | I2336: =VLOOKUP(A2336,'DATA TRANSFORMATION 3'!A:C,3,FALSE) -> No | J2336: =VLOOKUP(A2336,'DATA TRANSFORMATION 4'!A:C,3,FALSE) -> Under Weight | K2336: =VLOOKUP(A2336,'DATA TRANSFORMATION 5'!A:C,3,FALSE) -> Normal | L2336: =VLOOKUP(A2336,'DATA TRANSFORMATION 6'!A:E,5,FALSE) -> 4-Sep-1963 | M2336: =VLOOKUP(A2336,'DATA TRANSFORMATION 8'!A:B,2,FALSE) -> 48970.25 | N2336: =VLOOKUP(A2336,'DATA CLEANING 3'!A:D,3,FALSE) -> tier - 1 | O2336: =VLOOKUP(A2336,'DATA CLEANING 3'!A:D,4,FALSE) -> tier - 2 | P2336: =VLOOKUP(A2336,'DATA CLEANING 4'!A:B,2,FALSE) -> R1013 | Q2336: =VLOOKUP(A2336,'DATA TANSFORMATION 7'!A:F,6,FALSE) -> 59

Sheet DONUT & PIE CHART
A1: Analysis using Pie/Donut Chart:
A2: ➢ What is the distribution of cancer history among smokers and non-smokers?
A4: Count of Customer ID | B4: Column Labels
A5: Row Labels | B5: No | C5: Yes | D5: Grand Total
A6: No | B6: 1540 | C6: 307 | D6: 1847
A7: Yes | B7: 404 | C7: 84 | D7: 488
A8: Grand Total | B8: 1944 | C8: 391 | D8: 2335
A19: ➢ How does the total number of major surgeries and average HbA1C differ between patients with and without a history of transplants?
A21: Row Labels | B21: Sum of Number Of Major Surgeries | C21: Average of HBA1C
A22: No | B22: 1417 | C22: 6.6704427
A23: yes | B23: 162 | C23: 5.1876389
A24: Grand Total | B24: 1579 | C24: 6.5789979

Sheet COLUMN & BAR CHART
A1: Analysis using Column/Bar Chart:
A2: ➢ How do healthcare charges vary based on different weight statuses and diabetes statuses?
A4: Average of Charges | B4: Column Labels
A5: Row Labels | B5: Diabetes | C5: Normal | D5: Prediabetes | E5: Grand Total
A6: Normal Weight | B6: 11479.97 | C6: 20543.856 | D6: 18540.769 | E6: 17284.97
A7: Obesity | B7: 7087.4227 | C7: 12339.852 | D7: 12153.11 | E7: 10483.967
A8: Over Weight | B8: 9134.9181 | C8: 15377.494 | D8: 16497.218 | E8: 13662.615
A9: Under Weight | B9: 17912.901 | C9: 26863.078 | D9: 25824.313 | E9: 23386.455
A10: Grand Total | B10: 9173.7453 | C10: 15700.448 | D10: 15200.076 | E10: 13411.324
A17: ➢ Can you compare the average charges for each hospital tier within different states?
A19: Average of Charges | B19: Column Labels
A20: Row Labels | B20: tier - 1 | C20: tier - 2 | D20: tier - 3 | E20: Grand Total
A21: R1011 | B21: 32861.436 | C21: 18997.281 | D21: 9250.3618 | E21: 19445.172
A22: R1012 | B22: 24775.306 | C22: 10312.047 | D22: 10179.942 | E22: 11831.817
A23: R1013 | B23: 30888.292 | C23: 8183.81 | D23: 6857.1092 | E23: 10302.197
A24: R1014 | B24: 13891.86 | C24: 2395.17 | D24: 16950.485 | E24: 13478.057
A25: R1015 | B25: 21523.52 | C25: 16433.907 | D25: 7570.755 | E25: 14489.801
A26: R1016 | B26: 39868.616 | C26: 16075.963 | D26: 8133.0084 | E26: 13589.263
A27: R1017 | B27: 34070.596 | C27: 11365.622 | D27: 8667.3662 | E27: 14806.108
A28: R1018 | B28: 33475.82 | C28: 10139.553 | D28: 12570.97 | E28: 13272.787
A29: R1019 | B29: 27621.61 | C29: 8116.72 | D29: 12706.976 | E29: 13633.143
A30: R1020 | C30: 6760.5433 | D30: 11716.453 | E30: 9238.4983
A31: R1021 | C31: 7668.1787 | D31: 11518.786 | E31: 8933.3781
A32: R1022 | C32: 10102.027 | D32: 11637.812 | E32: 10650.521
A33: R1023 | B33: 18261.757 | C33: 13457.095 | D33: 12785.637 | E33: 13786.149
A34: R1024 | B34: 30744.581 | C34: 10174.346 | D34: 13360.979 | E34: 12577.691
A35: R1025 | C35: 6886.0368 | D35: 10510.314 | E35: 8788.7823
A36: R1026 | B36: 18709.798 | C36: 11919.608 | D36: 12296.78 | E36: 12489.921
A37: UNKNOWN | B37: 20996.53 | E37: 20996.53
A38: Grand Total | B38: 29602.752 | C38: 11799.192 | D38: 9450.2733 | E38: 13411.324

Sheet LINE & SCATTER PLOT
A1: Analysis using Line / Scatter Plot: | P1: Customer ID | Q1: Age | R1: BMI | S1: HbA1C | AI1: Customer ID | AJ1: Age | AK1: Charges
P2: Id1 | Q2: =VLOOKUP(P2,'DATA TANSFORMATION 7'!A:F,6,FALSE) -> 30 | R2: =VLOOKUP(P2,'DATA TRANSFORMATION 4'!A:C,2,FALSE) -> 47.41 | S2: =VLOOKUP(P2,'DATA TRANSFORMATION 5'!A:C,2,FALSE) -> 7.47 | U2: ➢ Explore the relationship between age and healthcare charges. | AI2: Id1 | AJ2: =VLOOKUP(AI2,'DATA TANSFORMATION 7'!A:F,6,FALSE) -> 30 | AK2: =VLOOKUP(AI2,'DATA TRANSFORMATION 8'!A:B,2,FALSE) -> 563.84
A3: ➢ Is there any correlation between age and both BMI and HbA1C in the dataset? | P3: Id2 | Q3: =VLOOKUP(P3,'DATA TANSFORMATION 7'!A:F,6,FALSE) -> 30 | R3: =VLOOKUP(P3,'DATA TRANSFORMATION 4'!A:C,2,FALSE) -> 30.36 | S3: =VLOOKUP(P3,'DATA TRANSFORMATION 5'!A:C,2,FALSE) -> 5.77 | AI3: Id2 | AJ3: =VLOOKUP(AI3,'DATA TANSFORMATION 7'!A:F,6,FALSE) -> 30 | AK3: =VLOOKUP(AI3,'DATA TRANSFORMATION 8'!A:B,2,FALSE) -> 570.62
P4: Id3 | Q4: =VLOOKUP(P4,'DATA TANSFORMATION 7'!A:F,6,FALSE) -> 29 | R4: =VLOOKUP(P4,'DATA TRANSFORMATION 4'!A:C,2,FALSE) -> 34.485 | S4: =VLOOKUP(P4,'DATA TRANSFORMATION 5'!A:C,2,FALSE) -> 11.87 | AI4: Id3 | AJ4: =VLOOKUP(AI4,'DATA TANSFORMATION 7'!A:F,6,FALSE) -> 29 | AK4: =VLOOKUP(AI4,'DATA TRANSFORMATION 8'!A:B,2,FALSE) -> 600
P5: Id4 | Q5: =VLOOKUP(P5,'DATA TANSFORMATION 7'!A:F,6,FALSE) -> 30 | R5: =VLOOKUP(P5,'DATA TRANSFORMATION 4'!A:C,2,FALSE) -> 38.095 | S5: =VLOOKUP(P5,'DATA TRANSFORMATION 5'!A:C,2,FALSE) -> 6.05 | AI5: Id4 | AJ5: =VLOOKUP(AI5,'DATA TANSFORMATION 7'!A:F,6,FALSE) -> 30 | AK5: =VLOOKUP(AI5,'DATA TRANSFORMATION 8'!A:B,2,FALSE) -> 604.54
P6: Id5 | Q6: =VLOOKUP(P6,'DATA TANSFORMATION 7'!A:F,6,FALSE) -> 24 | R6: =VLOOKUP(P6,'DATA TRANSFORMATION 4'!A:C,2,FALSE) -> 35.53 | S6: =VLOOKUP(P6,'DATA TRANSFORMATION 5'!A:C,2,FALSE) -> 5.45 | AI6: Id5 | AJ6: =VLOOKUP(AI6,'DATA TANSFORMATION 7'!A:F,6,FALSE) -> 24 | AK6: =VLOOKUP(AI6,'DATA TRANSFORMATION 8'!A:B,2,FALSE) -> 637.26
P7: Id6 | Q7: =VLOOKUP(P7,'DATA TANSFORMATION 7'!A:F,6,FALSE) -> 21 | R7: =VLOOKUP(P7,'DATA TRANSFORMATION 4'!A:C,2,FALSE) -> 32.8 | S7: =VLOOKUP(P7,'DATA TRANSFORMATION 5'!A:C,2,FALSE) -> 6.59 | AI7: Id6 | AJ7: =VLOOKUP(AI7,'DATA TANSFORMATION 7'!A:F,6,FALSE) -> 21 | AK7: =VLOOKUP(AI7,'DATA TRANSFORMATION 8'!A:B,2,FALSE) -> 646.14
P8: Id7 | Q8: =VLOOKUP(P8,'DATA TANSFORMATION 7'!A:F,6,FALSE) -> 30 | R8: =VLOOKUP(P8,'DATA TRANSFORMATION 4'!A:C,2,FALSE) -> 36.4 | S8: =VLOOKUP(P8,'DATA TRANSFORMATION 5'!A:C,2,FALSE) -> 6.07 | AI8: Id7 | AJ8: =VLOOKUP(AI8,'DATA TANSFORMATION 7'!A:F,6,FALSE) -> 30 | AK8: =VLOOKUP(AI8,'DATA TRANSFORMATION 8'!A:B,2,FALSE) -> 650
P9: Id8 | Q9: =VLOOKUP(P9,'DATA TANSFORMATION 7'!A:F,6,FALSE) -> 27 | R9: =VLOOKUP(P9,'DATA TRANSFORMATION 4'!A:C,2,FALSE) -> 36.96 | S9: =VLOOKUP(P9,'DATA TRANSFORMATION 5'!A:C,2,FALSE) -> 7.93 | AI9: Id8 | AJ9: =VLOOKUP(AI9,'DATA TANSFORMATION 7'!A:F,6,FALSE) -> 27 | AK9: =VLOOKUP(AI9,'DATA TRANSFORMATION 8'!A:B,2,FALSE) -> 650
P10: Id9 | Q10: =VLOOKUP(P10,'DATA TANSFORMATION 7'!A:F,6,FALSE) -> 20 | R10: =VLOOKUP(P10,'DATA TRANSFORMATION 4'!A:C,2,FALSE) -> 41.14 | S10: =VLOOKUP(P10,'DATA TRANSFORMATION 5'!A:C,2,FALSE) -> 9.58 | AI10: Id9 | AJ10: =VLOOKUP(AI10,'DATA TANSFORMATION 7'!A:F,6,FALSE) -> 20 | AK10: =VLOOKUP(AI10,'DATA TRANSFORMATION 8'!A:B,2,FALSE) -> 668
P11: Id10 | Q11: =VLOOKUP(P11,'DATA TANSFORMATION 7'!A:F,6,FALSE) -> 25 | R11: =VLOOKUP(P11,'DATA TRANSFORMATION 4'!A:C,2,FALSE) -> 38.06 | S11: =VLOOKUP(P11,'DATA TRANSFORMATION 5'!A:C,2,FALSE) -> 10.79 | AI11: Id10 | AJ11: =VLOOKUP(AI11,'DATA TANSFORMATION 7'!A:F,6,FALSE) -> 25 | AK11: =VLOOKUP(AI11,'DATA TRANSFORMATION 8'!A:B,2,FALSE) -> 670
P12: Id11 | Q12: =VLOOKUP(P12,'DATA TANSFORMATION 7'!A:F,6,FALSE) -> 21 | R12: =VLOOKUP(P12,'DATA TRANSFORMATION 4'!A:C,2,FALSE) -> 37.7 | S12: =VLOOKUP(P12,'DATA TRANSFORMATION 5'!A:C,2,FALSE) -> 5.96 | AI12: Id11 | AJ12: =VLOOKUP(AI12,'DATA TANSFORMATION 7'!A:F,6,FALSE) -> 21 | AK12: =VLOOKUP(AI12,'DATA TRANSFORMATION 8'!A:B,2,FALSE) -> 687.54
P13: Id12 | Q13: =VLOOKUP(P13,'DATA TANSFORMATION 7'!A:F,6,FALSE) -> 23 | R13: =VLOOKUP(P13,'DATA TRANSFORMATION 4'!A:C,2,FALSE) -> 42.13 | S13: =VLOOKUP(P13,'DATA TRANSFORMATION 5'!A:C,2,FALSE) -> 11.9 | AI13: Id12 | AJ13: =VLOOKUP(AI13,'DATA TANSFORMATION 7'!A:F,6,FALSE) -> 23 | AK13: =VLOOKUP(AI13,'DATA TRANSFORMATION 8'!A:B,2,FALSE) -> 700
P14: Id13 | Q14: =VLOOKUP(P14,'DATA TANSFORMATION 7'!A:F,6,FALSE) -> 23 | R14: =VLOOKUP(P14,'DATA TRANSFORMATION 4'!A:C,2,FALSE) -> 40.92 | S14: =VLOOKUP(P14,'DATA TRANSFORMATION 5'!A:C,2,FALSE) -> 8.41 | AI14: Id13 | AJ14: =VLOOKUP(AI14,'DATA TANSFORMATION 7'!A:F,6,FALSE) -> 23 | AK14: =VLOOKUP(AI14,'DATA TRANSFORMATION 8'!A:B,2,FALSE) -> 722.99
P15: Id14 | Q15: =VLOOKUP(P15,'DATA TANSFORMATION 7'!A:F,6,FALSE) -> 20 | R15: =VLOOKUP(P15,'DATA TRANSFORMATION 4'!A:C,2,FALSE) -> 40.565 | S15: =VLOOKUP(P15,'DATA TRANSFORMATION 5'!A:C,2,FALSE) -> 7.02 | AI15: Id14 | AJ15: =VLOOKUP(AI15,'DATA TANSFORMATION 7'!A:F,6,FALSE) -> 20 | AK15: =VLOOKUP(AI15,'DATA TRANSFORMATION 8'!A:B,2,FALSE) -> 750
... P2336: Id2335 | Q2336: =VLOOKUP(P2336,'DATA TANSFORMATION 7'!A:F,6,FALSE) -> 59 | R2336: =VLOOKUP(P2336,'DATA TRANSFORMATION 4'!A:C,2,FALSE) -> 17.58 | S2336: =VLOOKUP(P2336,'DATA TRANSFORMATION 5'!A:C,2,FALSE) -> 4.51 | AI2336: Id2335 | AJ2336: =VLOOKUP(AI2336,'DATA TANSFORMATION 7'!A:F,6,FALSE) -> 59 | AK2336: =VLOOKUP(AI2336,'DATA TRANSFORMATION 8'!A:B,2,FALSE) -> 48970.25

Sheet HEALTHCARE DASHBOARD
K3: HEALTHCARE INSIGHTS DASHBOARD
E35: Average of Charges | F35: Column Labels
E36: Row Labels | F36: Diabetes | G36: Normal | H36: Prediabetes | I36: Grand Total | L36: Count of Customer ID | M36: Column Labels
E37: Normal Weight | F37: 11479.97 | G37: 20543.856 | H37: 18540.769 | I37: 17284.97 | L37: Row Labels | M37: No | N37: Yes | O37: Grand Total
E38: Obesity | F38: 7087.4227 | G38: 12339.852 | H38: 12153.11 | I38: 10483.967 | L38: No | M38: 1540 | N38: 307 | O38: 1847
E39: Over Weight | F39: 9134.9181 | G39: 15377.494 | H39: 16497.218 | I39: 13662.615 | L39: Yes | M39: 404 | N39: 84 | O39: 488
E40: Under Weight | F40: 17912.901 | G40: 26863.078 | H40: 25824.313 | I40: 23386.455 | L40: Grand Total | M40: 1944 | N40: 391 | O40: 2335
E41: Grand Total | F41: 9173.7453 | G41: 15700.448 | H41: 15200.076 | I41: 13411.324
E61: Average of Charges | F61: Column Labels
E62: Row Labels | F62: tier - 1 | G62: tier - 2 | H62: tier - 3 | I62: Grand Total
E63: R1011 | F63: 32861.436 | G63: 18997.281 | H63: 9250.3618 | I63: 19445.172
E64: R1012 | F64: 24775.306 | G64: 10312.047 | H64: 10179.942 | I64: 11831.817
E65: R1013 | F65: 30888.292 | G65: 8183.81 | H65: 6857.1092 | I65: 10302.197
E66: R1014 | F66: 13891.86 | G66: 2395.17 | H66: 16950.485 | I66: 13478.057
E67: R1015 | F67: 21523.52 | G67: 16433.907 | H67: 7570.755 | I67: 14489.801
E68: R1016 | F68: 39868.616 | G68: 16075.963 | H68: 8133.0084 | I68: 13589.263
E69: R1017 | F69: 34070.596 | G69: 11365.622 | H69: 8667.3662 | I69: 14806.108
E70: R1018 | F70: 33475.82 | G70: 10139.553 | H70: 12570.97 | I70: 13272.787 | L70: Row Labels | M70: Sum of Number Of Major Surgeries | N70: Average of HBA1C
E71: R1019 | F71: 27621.61 | G71: 8116.72 | H71: 12706.976 | I71: 13633.143 | L71: No | M71: 1417 | N71: 6.6704427
E72: R1020 | G72: 6760.5433 | H72: 11716.453 | I72: 9238.4983 | L72: yes | M72: 162 | N72: 5.1876389
E73: R1021 | G73: 7668.1787 | H73: 11518.786 | I73: 8933.3781 | L73: Grand Total | M73: 1579 | N73: 6.5789979
E74: R1022 | G74: 10102.027 | H74: 11637.812 | I74: 10650.521
E75: R1023 | F75: 18261.757 | G75: 13457.095 | H75: 12785.637 | I75: 13786.149
E76: R1024 | F76: 30744.581 | G76: 10174.346 | H76: 13360.979 | I76: 12577.691
E77: R1025 | G77: 6886.0368 | H77: 10510.314 | I77: 8788.7823
E78: R1026 | F78: 18709.798 | G78: 11919.608 | H78: 12296.78 | I78: 12489.921
E79: UNKNOWN | F79: 20996.53 | I79: 20996.53
E80: Grand Total | F80: 29602.752 | G80: 11799.192 | H80: 9450.2733 | I80: 13411.324
